Workbook

Sheet Objective
B2: OBJECTIVE | K2: Buckets created after combining similar categories
K3: Food & Beverages | L3: Energy | M3: Transportation | N3: Education | O3: Health and Personal care | P3: Housing and Household | Q3: Clothing and Footwear | R3: Recreation and miscellaneous
K4: Cereals and products | L4: Fuel and light | M4: Transport and communication | N4: Education | O4: Health | P4: Housing | Q4: Clothing | R4: Pan, tobacco and intoxicants
K5: Meat and fish | O5: Personal care and effects | P5: Household goods and services | Q5: Footwear | R5: Recreation and amusement
K6: Egg | Q6: Clothing and footwear | R6: Miscellaneous
K7: Milk and products
K8: Oils and fats
K9: Fruits
K10: Vegetables
K11: Pulses and products
K12: Sugar and Confectionery
K13: Spices
K14: Non-alcoholic beverages
K15: Prepared meals, snacks, sweets etc.
K16: Food and beverages

Sheet Original Data
A1: Sector | B1: Year | C1: Month | D1: Cereals and products | E1: Meat and fish | F1: Egg | G1: Milk and products | H1: Oils and fats | I1: Fruits | J1: Vegetables | K1: Pulses and products | L1: Sugar and Confectionery | M1: Spices | N1: Non-alcoholic beverages | O1: Prepared meals, snacks, sweets etc. | P1: Food and beverages | Q1: Pan, tobacco and intoxicants | R1: Clothing | S1: Footwear | T1: Clothing and footwear | U1: Housing | V1: Fuel and light | W1: Household goods and services | X1: Health | Y1: Transport and communication | Z1: Recreation and amusement | AA1: Education | AB1: Personal care and effects | AC1: Miscellaneous | AD1: General index
A2: Rural | B2: 2013 | C2: January | D2: 107.5 | E2: 106.3 | F2: 108.1 | G2: 104.9 | H2: 106.1 | I2: 103.9 | J2: 101.9 | K2: 106.1 | L2: 106.8 | M2: 103.1 | N2: 104.8 | O2: 106.7 | P2: 105.5 | Q2: 105.1 | R2: 106.5 | S2: 105.8 | T2: 106.4 | U2: NA | V2: 105.5 | W2: 104.8 | X2: 104 | Y2: 103.3 | Z2: 103.4 | AA2: 103.8 | AB2: 104.7 | AC2: 104 | AD2: 105.1
A3: Urban | B3: 2013 | C3: January | D3: 110.5 | E3: 109.1 | F3: 113 | G3: 103.6 | H3: 103.4 | I3: 102.3 | J3: 102.9 | K3: 105.8 | L3: 105.1 | M3: 101.8 | N3: 105.1 | O3: 107.9 | P3: 105.9 | Q3: 105.2 | R3: 105.9 | S3: 105 | T3: 105.8 | U3: 100.3 | V3: 105.4 | W3: 104.8 | X3: 104.1 | Y3: 103.2 | Z3: 102.9 | AA3: 103.5 | AB3: 104.3 | AC3: 103.7 | AD3: 104
A4: Rural+Urban | B4: 2013 | C4: January | D4: 108.4 | E4: 107.3 | F4: 110 | G4: 104.4 | H4: 105.1 | I4: 103.2 | J4: 102.2 | K4: 106 | L4: 106.2 | M4: 102.7 | N4: 104.9 | O4: 107.3 | P4: 105.6 | Q4: 105.1 | R4: 106.3 | S4: 105.5 | T4: 106.2 | U4: 100.3 | V4: 105.5 | W4: 104.8 | X4: 104 | Y4: 103.2 | Z4: 103.1 | AA4: 103.6 | AB4: 104.5 | AC4: 103.9 | AD4: 104.6
A5: Rural | B5: 2013 | C5: February | D5: 109.2 | E5: 108.7 | F5: 110.2 | G5: 105.4 | H5: 106.7 | I5: 104 | J5: 102.4 | K5: 105.9 | L5: 105.7 | M5: 103.1 | N5: 105.1 | O5: 107.7 | P5: 106.3 | Q5: 105.6 | R5: 107.1 | S5: 106.3 | T5: 107 | U5: NA | V5: 106.2 | W5: 105.2 | X5: 104.4 | Y5: 103.9 | Z5: 104 | AA5: 104.1 | AB5: 104.6 | AC5: 104.4 | AD5: 105.8
A6: Urban | B6: 2013 | C6: February | D6: 112.9 | E6: 112.9 | F6: 116.9 | G6: 104 | H6: 103.5 | I6: 103.1 | J6: 104.9 | K6: 104.1 | L6: 103.8 | M6: 102.3 | N6: 106 | O6: 109 | P6: 107.2 | Q6: 106 | R6: 106.6 | S6: 105.5 | T6: 106.4 | U6: 100.4 | V6: 105.7 | W6: 105.2 | X6: 104.7 | Y6: 104.4 | Z6: 103.3 | AA6: 103.7 | AB6: 104.3 | AC6: 104.3 | AD6: 104.7
A7: Rural+Urban | B7: 2013 | C7: February | D7: 110.4 | E7: 110.2 | F7: 112.8 | G7: 104.9 | H7: 105.5 | I7: 103.6 | J7: 103.2 | K7: 105.3 | L7: 105.1 | M7: 102.8 | N7: 105.5 | O7: 108.3 | P7: 106.6 | Q7: 105.7 | R7: 106.9 | S7: 106 | T7: 106.8 | U7: 100.4 | V7: 106 | W7: 105.2 | X7: 104.5 | Y7: 104.2 | Z7: 103.6 | AA7: 103.9 | AB7: 104.5 | AC7: 104.4 | AD7: 105.3
A8: Rural | B8: 2013 | C8: March | D8: 110.2 | E8: 108.8 | F8: 109.9 | G8: 105.6 | H8: 106.2 | I8: 105.7 | J8: 101.4 | K8: 105.7 | L8: 105 | M8: 103.3 | N8: 105.6 | O8: 108.2 | P8: 106.6 | Q8: 106.5 | R8: 107.6 | S8: 106.8 | T8: 107.5 | U8: NA | V8: 106.1 | W8: 105.6 | X8: 104.7 | Y8: 104.6 | Z8: 104 | AA8: 104.3 | AB8: 104.3 | AC8: 104.6 | AD8: 106
A9: Urban | B9: 2013 | C9: March | D9: 113.9 | E9: 111.4 | F9: 113.2 | G9: 104.3 | H9: 102.7 | I9: 104.9 | J9: 103.8 | K9: 103.5 | L9: 102.6 | M9: 102.4 | N9: 107 | O9: 109.8 | P9: 107.3 | Q9: 106.8 | R9: 107.2 | S9: 106 | T9: 107 | U9: 100.4 | V9: 106 | W9: 105.7 | X9: 105.2 | Y9: 105.5 | Z9: 103.5 | AA9: 103.8 | AB9: 104.2 | AC9: 104.9 | AD9: 105
A10: Rural+Urban | B10: 2013 | C10: March | D10: 111.4 | E10: 109.7 | F10: 111.2 | G10: 105.1 | H10: 104.9 | I10: 105.3 | J10: 102.2 | K10: 105 | L10: 104.2 | M10: 103 | N10: 106.2 | O10: 108.9 | P10: 106.9 | Q10: 106.6 | R10: 107.4 | S10: 106.5 | T10: 107.3 | U10: 100.4 | V10: 106.1 | W10: 105.6 | X10: 104.9 | Y10: 105.1 | Z10: 103.7 | AA10: 104 | AB10: 104.3 | AC10: 104.7 | AD10: 105.5
A11: Rural | B11: 2013 | C11: April | D11: 110.2 | E11: 109.5 | F11: 106.9 | G11: 106.3 | H11: 105.7 | I11: 108.3 | J11: 103.4 | K11: 105.7 | L11: 104.2 | M11: 103.2 | N11: 106.5 | O11: 108.8 | P11: 107.1 | Q11: 107.1 | R11: 108.1 | S11: 107.4 | T11: 108 | U11: NA | V11: 106.5 | W11: 106.1 | X11: 105.1 | Y11: 104.4 | Z11: 104.5 | AA11: 104.8 | AB11: 102.7 | AC11: 104.6 | AD11: 106.4
A12: Urban | B12: 2013 | C12: April | D12: 114.6 | E12: 113.4 | F12: 106 | G12: 104.7 | H12: 102.1 | I12: 109.5 | J12: 109.7 | K12: 104.6 | L12: 102 | M12: 103.5 | N12: 108.2 | O12: 110.6 | P12: 108.8 | Q12: 108.5 | R12: 107.9 | S12: 106.4 | T12: 107.7 | U12: 100.5 | V12: 106.4 | W12: 106.5 | X12: 105.7 | Y12: 105 | Z12: 104 | AA12: 105.2 | AB12: 103.2 | AC12: 105.1 | AD12: 105.7
A13: Rural+Urban | B13: 2013 | C13: April | D13: 111.6 | E13: 110.9 | F13: 106.6 | G13: 105.7 | H13: 104.4 | I13: 108.9 | J13: 105.5 | K13: 105.3 | L13: 103.5 | M13: 103.3 | N13: 107.2 | O13: 109.6 | P13: 107.7 | Q13: 107.5 | R13: 108 | S13: 107 | T13: 107.9 | U13: 100.5 | V13: 106.5 | W13: 106.3 | X13: 105.3 | Y13: 104.7 | Z13: 104.2 | AA13: 105 | AB13: 102.9 | AC13: 104.8 | AD13: 106.1
A14: Rural | B14: 2013 | C14: May | D14: 110.9 | E14: 109.8 | F14: 105.9 | G14: 107.5 | H14: 105.3 | I14: 108.1 | J14: 107.3 | K14: 106.1 | L14: 103.7 | M14: 104 | N14: 107.4 | O14: 109.9 | P14: 108.1 | Q14: 108.1 | R14: 108.8 | S14: 107.9 | T14: 108.6 | U14: NA | V14: 107.5 | W14: 106.8 | X14: 105.7 | Y14: 104.1 | Z14: 105 | AA14: 105.5 | AB14: 102.1 | AC14: 104.8 | AD14: 107.2
A15: Urban | B15: 2013 | C15: May | D15: 115.4 | E15: 114.2 | F15: 102.7 | G15: 105.5 | H15: 101.5 | I15: 110.6 | J15: 123.7 | K15: 105.2 | L15: 101.9 | M15: 105 | N15: 109.1 | O15: 111.3 | P15: 111.1 | Q15: 109.8 | R15: 108.5 | S15: 106.7 | T15: 108.3 | U15: 100.5 | V15: 107.2 | W15: 107.1 | X15: 106.2 | Y15: 103.9 | Z15: 104.6 | AA15: 105.7 | AB15: 102.6 | AC15: 104.9 | AD15: 106.6
A16: Rural+Urban | B16: 2013 | C16: May | D16: 112.3 | E16: 111.3 | F16: 104.7 | G16: 106.8 | H16: 103.9 | I16: 109.3 | J16: 112.9 | K16: 105.8 | L16: 103.1 | M16: 104.3 | N16: 108.1 | O16: 110.5 | P16: 109.2 | Q16: 108.6 | R16: 108.7 | S16: 107.4 | T16: 108.5 | U16: 100.5 | V16: 107.4 | W16: 106.9 | X16: 105.9 | Y16: 104 | Z16: 104.8 | AA16: 105.6 | AB16: 102.3 | AC16: 104.8 | AD16: 106.9
A17: Rural | B17: 2013 | C17: June | D17: 112.3 | E17: 112.1 | F17: 108.1 | G17: 108.3 | H17: 105.9 | I17: 109.2 | J17: 118 | K17: 106.8 | L17: 104.1 | M17: 105.4 | N17: 108.2 | O17: 111 | P17: 110.6 | Q17: 109 | R17: 109.7 | S17: 108.8 | T17: 109.5 | U17: NA | V17: 108.5 | W17: 107.5 | X17: 106.3 | Y17: 105 | Z17: 105.6 | AA17: 106.5 | AB17: 102.5 | AC17: 105.5 | AD17: 108.9
A18: Urban | B18: 2013 | C18: June | D18: 117 | E18: 120.1 | F18: 112.5 | G18: 107.3 | H18: 101.3 | I18: 112.4 | J18: 143.6 | K18: 105.4 | L18: 101.4 | M18: 106.4 | N18: 110 | O18: 112.2 | P18: 115 | Q18: 110.9 | R18: 109.2 | S18: 107.2 | T18: 108.9 | U18: 106.6 | V18: 108 | W18: 107.7 | X18: 106.5 | Y18: 105.2 | Z18: 105.2 | AA18: 108.1 | AB18: 103.3 | AC18: 106.1 | AD18: 109.7
A19: Rural+Urban | B19: 2013 | C19: June | D19: 113.8 | E19: 114.9 | F19: 109.8 | G19: 107.9 | H19: 104.2 | I19: 110.7 | J19: 126.7 | K19: 106.3 | L19: 103.2 | M19: 105.7 | N19: 109 | O19: 111.6 | P19: 112.2 | Q19: 109.5 | R19: 109.5 | S19: 108.1 | T19: 109.3 | U19: 106.6 | V19: 108.3 | W19: 107.6 | X19: 106.4 | Y19: 105.1 | Z19: 105.4 | AA19: 107.4 | AB19: 102.8 | AC19: 105.8 | AD19: 109.3
A20: Rural | B20: 2013 | C20: July | D20: 113.4 | E20: 114.9 | F20: 110.5 | G20: 109.3 | H20: 106.2 | I20: 110.3 | J20: 129.2 | K20: 107.1 | L20: 104.3 | M20: 106.4 | N20: 109.1 | O20: 112.1 | P20: 113.1 | Q20: 109.8 | R20: 110.5 | S20: 109.5 | T20: 110.3 | U20: NA | V20: 109.5 | W20: 108.3 | X20: 106.9 | Y20: 106.8 | Z20: 106.4 | AA20: 107.8 | AB20: 102.5 | AC20: 106.5 | AD20: 110.7
A21: Urban | B21: 2013 | C21: July | D21: 117.8 | E21: 119.2 | F21: 114 | G21: 108.3 | H21: 101.1 | I21: 113.2 | J21: 160.9 | K21: 105.1 | L21: 101.3 | M21: 107.5 | N21: 110.4 | O21: 113.1 | P21: 117.5 | Q21: 111.7 | R21: 109.8 | S21: 107.8 | T21: 109.5 | U21: 107.7 | V21: 108.6 | W21: 108.1 | X21: 107.1 | Y21: 107.3 | Z21: 105.9 | AA21: 110.1 | AB21: 103.2 | AC21: 107.3 | AD21: 111.4
A22: Rural+Urban | B22: 2013 | C22: July | D22: 114.8 | E22: 116.4 | F22: 111.9 | G22: 108.9 | H22: 104.3 | I22: 111.7 | J22: 140 | K22: 106.4 | L22: 103.3 | M22: 106.8 | N22: 109.6 | O22: 112.6 | P22: 114.7 | Q22: 110.3 | R22: 110.2 | S22: 108.8 | T22: 110 | U22: 107.7 | V22: 109.2 | W22: 108.2 | X22: 107 | Y22: 107.1 | Z22: 106.1 | AA22: 109.1 | AB22: 102.8 | AC22: 106.9 | AD22: 111
A23: Rural | B23: 2013 | C23: August | D23: 114.3 | E23: 115.4 | F23: 111.1 | G23: 110 | H23: 106.4 | I23: 110.8 | J23: 138.9 | K23: 107.4 | L23: 104.1 | M23: 106.9 | N23: 109.7 | O23: 112.6 | P23: 114.9 | Q23: 110.7 | R23: 111.3 | S23: 110.2 | T23: 111.1 | U23: NA | V23: 109.9 | W23: 108.7 | X23: 107.5 | Y23: 107.8 | Z23: 106.8 | AA23: 108.7 | AB23: 105 | AC23: 107.5 | AD23: 112.1
A24: Urban | B24: 2013 | C24: August | D24: 118.3 | E24: 120.4 | F24: 112.7 | G24: 108.9 | H24: 101.1 | I24: 108.7 | J24: 177 | K24: 104.7 | L24: 101 | M24: 108.5 | N24: 110.9 | O24: 114.3 | P24: 119.6 | Q24: 112.4 | R24: 110.6 | S24: 108.3 | T24: 110.2 | U24: 108.9 | V24: 109.3 | W24: 108.7 | X24: 107.6 | Y24: 108.1 | Z24: 106.5 | AA24: 110.8 | AB24: 106 | AC24: 108.3 | AD24: 112.7
A25: Rural+Urban | B25: 2013 | C25: August | D25: 115.6 | E25: 117.2 | F25: 111.7 | G25: 109.6 | H25: 104.5 | I25: 109.8 | J25: 151.8 | K25: 106.5 | L25: 103.1 | M25: 107.4 | N25: 110.2 | O25: 113.4 | P25: 116.6 | Q25: 111.2 | R25: 111 | S25: 109.4 | T25: 110.7 | U25: 108.9 | V25: 109.7 | W25: 108.7 | X25: 107.5 | Y25: 108 | Z25: 106.6 | AA25: 109.9 | AB25: 105.4 | AC25: 107.9 | AD25: 112.4
A26: Rural | B26: 2013 | C26: September | D26: 115.4 | E26: 115.7 | F26: 111.7 | G26: 111 | H26: 107.4 | I26: 110.9 | J26: 154 | K26: 108.1 | L26: 104.2 | M26: 107.9 | N26: 110.4 | O26: 114 | P26: 117.8 | Q26: 111.7 | R26: 112.7 | S26: 111.4 | T26: 112.5 | U26: NA | V26: 111.1 | W26: 109.6 | X26: 108.3 | Y26: 109.3 | Z26: 107.7 | AA26: 109.8 | AB26: 106.7 | AC26: 108.7 | AD26: 114.2
A27: Urban | B27: 2013 | C27: September | D27: 118.6 | E27: 119.1 | F27: 113.2 | G27: 109.6 | H27: 101.7 | I27: 103.2 | J27: 174.3 | K27: 105.1 | L27: 100.8 | M27: 109.1 | N27: 111.1 | O27: 115.4 | P27: 119.2 | Q27: 112.9 | R27: 111.4 | S27: 109 | T27: 111.1 | U27: 109.7 | V27: 109.5 | W27: 109.6 | X27: 107.9 | Y27: 110.4 | Z27: 107.4 | AA27: 111.2 | AB27: 106.9 | AC27: 109.4 | AD27: 113.2
A28: Rural+Urban | B28: 2013 | C28: September | D28: 116.4 | E28: 116.9 | F28: 112.3 | G28: 110.5 | H28: 105.3 | I28: 107.3 | J28: 160.9 | K28: 107.1 | L28: 103.1 | M28: 108.3 | N28: 110.7 | O28: 114.6 | P28: 118.3 | Q28: 112 | R28: 112.2 | S28: 110.4 | T28: 111.9 | U28: 109.7 | V28: 110.5 | W28: 109.6 | X28: 108.1 | Y28: 109.9 | Z28: 107.5 | AA28: 110.6 | AB28: 106.8 | AC28: 109 | AD28: 113.7
A29: Rural | B29: 2013 | C29: October | D29: 116.3 | E29: 115.4 | F29: 112.6 | G29: 111.7 | H29: 107.7 | I29: 113.2 | J29: 164.9 | K29: 108.3 | L29: 103.9 | M29: 108.2 | N29: 111.1 | O29: 114.9 | P29: 119.8 | Q29: 112.2 | R29: 113.6 | S29: 112.3 | T29: 113.4 | U29: NA | V29: 111.6 | W29: 110.4 | X29: 108.9 | Y29: 109.3 | Z29: 108.3 | AA29: 110.2 | AB29: 107.5 | AC29: 109.1 | AD29: 115.5
A30: Urban | B30: 2013 | C30: October | D30: 118.9 | E30: 118.1 | F30: 114.5 | G30: 110.4 | H30: 102.3 | I30: 106.2 | J30: 183.5 | K30: 105.3 | L30: 100.2 | M30: 109.6 | N30: 111.4 | O30: 116 | P30: 120.8 | Q30: 113.5 | R30: 112.5 | S30: 109.7 | T30: 112 | U30: 110.5 | V30: 109.7 | W30: 110.2 | X30: 108.2 | Y30: 109.7 | Z30: 108 | AA30: 111.3 | AB30: 107.3 | AC30: 109.4 | AD30: 114
A31: Rural+Urban | B31: 2013 | C31: October | D31: 117.1 | E31: 116.3 | F31: 113.3 | G31: 111.2 | H31: 105.7 | I31: 109.9 | J31: 171.2 | K31: 107.3 | L31: 102.7 | M31: 108.7 | N31: 111.2 | O31: 115.4 | P31: 120.2 | Q31: 112.5 | R31: 113.2 | S31: 111.2 | T31: 112.8 | U31: 110.5 | V31: 110.9 | W31: 110.3 | X31: 108.6 | Y31: 109.5 | Z31: 108.1 | AA31: 110.8 | AB31: 107.4 | AC31: 109.2 | AD31: 114.8
A32: Rural | B32: 2013 | C32: November | D32: 117.3 | E32: 114.9 | F32: 116.2 | G32: 112.8 | H32: 108.9 | I32: 116.6 | J32: 178.1 | K32: 109.1 | L32: 103.6 | M32: 109 | N32: 111.8 | O32: 116 | P32: 122.5 | Q32: 112.8 | R32: 114.6 | S32: 113.1 | T32: 114.4 | U32: NA | V32: 112.6 | W32: 111.3 | X32: 109.7 | Y32: 109.6 | Z32: 108.7 | AA32: 111 | AB32: 108.2 | AC32: 109.8 | AD32: 117.4
A33: Urban | B33: 2013 | C33: November | D33: 119.8 | E33: 116.3 | F33: 122.6 | G33: 112 | H33: 103.2 | I33: 110 | J33: 192.8 | K33: 106.3 | L33: 99.5 | M33: 110.3 | N33: 111.8 | O33: 117.1 | P33: 122.9 | Q33: 114.1 | R33: 113.5 | S33: 110.3 | T33: 113 | U33: 111.1 | V33: 110 | W33: 110.9 | X33: 108.6 | Y33: 109.5 | Z33: 108.5 | AA33: 111.3 | AB33: 107.9 | AC33: 109.6 | AD33: 115
A34: Rural+Urban | B34: 2013 | C34: November | D34: 118.1 | E34: 115.4 | F34: 118.7 | G34: 112.5 | H34: 106.8 | I34: 113.5 | J34: 183.1 | K34: 108.2 | L34: 102.2 | M34: 109.4 | N34: 111.8 | O34: 116.5 | P34: 122.6 | Q34: 113.1 | R34: 114.2 | S34: 111.9 | T34: 113.8 | U34: 111.1 | V34: 111.6 | W34: 111.1 | X34: 109.3 | Y34: 109.5 | Z34: 108.6 | AA34: 111.2 | AB34: 108.1 | AC34: 109.7 | AD34: 116.3
A35: Rural | B35: 2013 | C35: December | D35: 118.4 | E35: 115.9 | F35: 120.4 | G35: 113.8 | H35: 109.5 | I35: 115.5 | J35: 145.7 | K35: 109.5 | L35: 102.9 | M35: 109.8 | N35: 112.1 | O35: 116.8 | P35: 118.7 | Q35: 113.6 | R35: 115.8 | S35: 114 | T35: 115.5 | U35: NA | V35: 112.8 | W35: 112.1 | X35: 110.1 | Y35: 109.9 | Z35: 109.2 | AA35: 111.6 | AB35: 108.1 | AC35: 110.1 | AD35: 115.5
A36: Urban | B36: 2013 | C36: December | D36: 120.5 | E36: 118.1 | F36: 128.5 | G36: 112.8 | H36: 103.4 | I36: 110.7 | J36: 144.8 | K36: 107.1 | L36: 98.6 | M36: 111.9 | N36: 112.1 | O36: 118.1 | P36: 117.8 | Q36: 115 | R36: 114.2 | S36: 110.9 | T36: 113.7 | U36: 110.7 | V36: 110.4 | W36: 111.3 | X36: 109 | Y36: 109.7 | Z36: 108.9 | AA36: 111.4 | AB36: 107.7 | AC36: 109.8 | AD36: 113.3
A37: Rural+Urban | B37: 2013 | C37: December | D37: 119.1 | E37: 116.7 | F37: 123.5 | G37: 113.4 | H37: 107.3 | I37: 113.3 | J37: 145.4 | K37: 108.7 | L37: 101.5 | M37: 110.5 | N37: 112.1 | O37: 117.4 | P37: 118.4 | Q37: 114 | R37: 115.2 | S37: 112.7 | T37: 114.8 | U37: 110.7 | V37: 111.9 | W37: 111.7 | X37: 109.7 | Y37: 109.8 | Z37: 109 | AA37: 111.5 | AB37: 107.9 | AC37: 110 | AD37: 114.5
A38: Rural | B38: 2014 | C38: January | D38: 118.9 | E38: 117.1 | F38: 120.5 | G38: 114.4 | H38: 109 | I38: 115.5 | J38: 123.9 | K38: 109.6 | L38: 101.8 | M38: 110.2 | N38: 112.4 | O38: 117.3 | P38: 116 | Q38: 114 | R38: 116.5 | S38: 114.5 | T38: 116.2 | U38: NA | V38: 113 | W38: 112.6 | X38: 110.6 | Y38: 110.5 | Z38: 109.6 | AA38: 111.8 | AB38: 108.3 | AC38: 110.6 | AD38: 114.2
A39: Urban | B39: 2014 | C39: January | D39: 121.2 | E39: 122 | F39: 129.9 | G39: 113.6 | H39: 102.9 | I39: 112.1 | J39: 118.9 | K39: 107.5 | L39: 96.9 | M39: 112.7 | N39: 112.1 | O39: 119 | P39: 115.5 | Q39: 115.7 | R39: 114.8 | S39: 111.3 | T39: 114.3 | U39: 111.6 | V39: 111 | W39: 111.9 | X39: 109.7 | Y39: 110.8 | Z39: 109.8 | AA39: 111.5 | AB39: 108 | AC39: 110.5 | AD39: 112.9
A40: Rural+Urban | B40: 2014 | C40: January | D40: 119.6 | E40: 118.8 | F40: 124.1 | G40: 114.1 | H40: 106.8 | I40: 113.9 | J40: 122.2 | K40: 108.9 | L40: 100.2 | M40: 111 | N40: 112.3 | O40: 118.1 | P40: 115.8 | Q40: 114.5 | R40: 115.8 | S40: 113.2 | T40: 115.4 | U40: 111.6 | V40: 112.2 | W40: 112.3 | X40: 110.3 | Y40: 110.7 | Z40: 109.7 | AA40: 111.6 | AB40: 108.2 | AC40: 110.6 | AD40: 113.6
...

Sheet Working Data
A1: Sector | B1: Year | C1: Month | D1: Cereals and products | E1: Meat and fish | F1: Egg | G1: Milk and products | H1: Oils and fats | I1: Fruits | J1: Vegetables | K1: Pulses and products | L1: Sugar and Confectionery | M1: Spices | N1: Non-alcoholic beverages | O1: Prepared meals, snacks, sweets etc. | P1: Food and beverages | Q1: Pan, tobacco and intoxicants | R1: Clothing | S1: Footwear | T1: Clothing and footwear | U1: Housing | V1: Fuel and light | W1: Household goods and services | X1: Health | Y1: Transport and communication | Z1: Recreation and amusement | AA1: Education | AB1: Personal care and effects | AC1: Miscellaneous | AD1: General index
A2: Rural | B2: 2013 | C2: January | D2: 107.5 | E2: 106.3 | F2: 108.1 | G2: 104.9 | H2: 106.1 | I2: 103.9 | J2: 101.9 | K2: 106.1 | L2: 106.8 | M2: 103.1 | N2: 104.8 | O2: 106.7 | P2: 105.5 | Q2: 105.1 | R2: 106.5 | S2: 105.8 | T2: 106.4 | U2: 100.3 | V2: 105.5 | W2: 104.8 | X2: 104 | Y2: 103.3 | Z2: 103.4 | AA2: 103.8 | AB2: 104.7 | AC2: 104 | AD2: 105.1
A3: Urban | B3: 2013 | C3: January | D3: 110.5 | E3: 109.1 | F3: 113 | G3: 103.6 | H3: 103.4 | I3: 102.3 | J3: 102.9 | K3: 105.8 | L3: 105.1 | M3: 101.8 | N3: 105.1 | O3: 107.9 | P3: 105.9 | Q3: 105.2 | R3: 105.9 | S3: 105 | T3: 105.8 | U3: 100.3 | V3: 105.4 | W3: 104.8 | X3: 104.1 | Y3: 103.2 | Z3: 102.9 | AA3: 103.5 | AB3: 104.3 | AC3: 103.7 | AD3: 104
A4: Rural+Urban | B4: 2013 | C4: January | D4: 108.4 | E4: 107.3 | F4: 110 | G4: 104.4 | H4: 105.1 | I4: 103.2 | J4: 102.2 | K4: 106 | L4: 106.2 | M4: 102.7 | N4: 104.9 | O4: 107.3 | P4: 105.6 | Q4: 105.1 | R4: 106.3 | S4: 105.5 | T4: 106.2 | U4: 100.3 | V4: 105.5 | W4: 104.8 | X4: 104 | Y4: 103.2 | Z4: 103.1 | AA4: 103.6 | AB4: 104.5 | AC4: 103.9 | AD4: 104.6
A5: Rural | B5: 2013 | C5: February | D5: 109.2 | E5: 108.7 | F5: 110.2 | G5: 105.4 | H5: 106.7 | I5: 104 | J5: 102.4 | K5: 105.9 | L5: 105.7 | M5: 103.1 | N5: 105.1 | O5: 107.7 | P5: 106.3 | Q5: 105.6 | R5: 107.1 | S5: 106.3 | T5: 107 | U5: 100.4 | V5: 106.2 | W5: 105.2 | X5: 104.4 | Y5: 103.9 | Z5: 104 | AA5: 104.1 | AB5: 104.6 | AC5: 104.4 | AD5: 105.8
A6: Urban | B6: 2013 | C6: February | D6: 112.9 | E6: 112.9 | F6: 116.9 | G6: 104 | H6: 103.5 | I6: 103.1 | J6: 104.9 | K6: 104.1 | L6: 103.8 | M6: 102.3 | N6: 106 | O6: 109 | P6: 107.2 | Q6: 106 | R6: 106.6 | S6: 105.5 | T6: 106.4 | U6: 100.4 | V6: 105.7 | W6: 105.2 | X6: 104.7 | Y6: 104.4 | Z6: 103.3 | AA6: 103.7 | AB6: 104.3 | AC6: 104.3 | AD6: 104.7
A7: Rural+Urban | B7: 2013 | C7: February | D7: 110.4 | E7: 110.2 | F7: 112.8 | G7: 104.9 | H7: 105.5 | I7: 103.6 | J7: 103.2 | K7: 105.3 | L7: 105.1 | M7: 102.8 | N7: 105.5 | O7: 108.3 | P7: 106.6 | Q7: 105.7 | R7: 106.9 | S7: 106 | T7: 106.8 | U7: 100.4 | V7: 106 | W7: 105.2 | X7: 104.5 | Y7: 104.2 | Z7: 103.6 | AA7: 103.9 | AB7: 104.5 | AC7: 104.4 | AD7: 105.3
A8: Rural | B8: 2013 | C8: March | D8: 110.2 | E8: 108.8 | F8: 109.9 | G8: 105.6 | H8: 106.2 | I8: 105.7 | J8: 101.4 | K8: 105.7 | L8: 105 | M8: 103.3 | N8: 105.6 | O8: 108.2 | P8: 106.6 | Q8: 106.5 | R8: 107.6 | S8: 106.8 | T8: 107.5 | U8: 100.4 | V8: 106.1 | W8: 105.6 | X8: 104.7 | Y8: 104.6 | Z8: 104 | AA8: 104.3 | AB8: 104.3 | AC8: 104.6 | AD8: 106
A9: Urban | B9: 2013 | C9: March | D9: 113.9 | E9: 111.4 | F9: 113.2 | G9: 104.3 | H9: 102.7 | I9: 104.9 | J9: 103.8 | K9: 103.5 | L9: 102.6 | M9: 102.4 | N9: 107 | O9: 109.8 | P9: 107.3 | Q9: 106.8 | R9: 107.2 | S9: 106 | T9: 107 | U9: 100.4 | V9: 106 | W9: 105.7 | X9: 105.2 | Y9: 105.5 | Z9: 103.5 | AA9: 103.8 | AB9: 104.2 | AC9: 104.9 | AD9: 105
A10: Rural+Urban | B10: 2013 | C10: March | D10: 111.4 | E10: 109.7 | F10: 111.2 | G10: 105.1 | H10: 104.9 | I10: 105.3 | J10: 102.2 | K10: 105 | L10: 104.2 | M10: 103 | N10: 106.2 | O10: 108.9 | P10: 106.9 | Q10: 106.6 | R10: 107.4 | S10: 106.5 | T10: 107.3 | U10: 100.4 | V10: 106.1 | W10: 105.6 | X10: 104.9 | Y10: 105.1 | Z10: 103.7 | AA10: 104 | AB10: 104.3 | AC10: 104.7 | AD10: 105.5
A11: Rural | B11: 2013 | C11: April | D11: 110.2 | E11: 109.5 | F11: 106.9 | G11: 106.3 | H11: 105.7 | I11: 108.3 | J11: 103.4 | K11: 105.7 | L11: 104.2 | M11: 103.2 | N11: 106.5 | O11: 108.8 | P11: 107.1 | Q11: 107.1 | R11: 108.1 | S11: 107.4 | T11: 108 | U11: 100.5 | V11: 106.5 | W11: 106.1 | X11: 105.1 | Y11: 104.4 | Z11: 104.5 | AA11: 104.8 | AB11: 102.7 | AC11: 104.6 | AD11: 106.4
A12: Urban | B12: 2013 | C12: April | D12: 114.6 | E12: 113.4 | F12: 106 | G12: 104.7 | H12: 102.1 | I12: 109.5 | J12: 109.7 | K12: 104.6 | L12: 102 | M12: 103.5 | N12: 108.2 | O12: 110.6 | P12: 108.8 | Q12: 108.5 | R12: 107.9 | S12: 106.4 | T12: 107.7 | U12: 100.5 | V12: 106.4 | W12: 106.5 | X12: 105.7 | Y12: 105 | Z12: 104 | AA12: 105.2 | AB12: 103.2 | AC12: 105.1 | AD12: 105.7
A13: Rural+Urban | B13: 2013 | C13: April | D13: 111.6 | E13: 110.9 | F13: 106.6 | G13: 105.7 | H13: 104.4 | I13: 108.9 | J13: 105.5 | K13: 105.3 | L13: 103.5 | M13: 103.3 | N13: 107.2 | O13: 109.6 | P13: 107.7 | Q13: 107.5 | R13: 108 | S13: 107 | T13: 107.9 | U13: 100.5 | V13: 106.5 | W13: 106.3 | X13: 105.3 | Y13: 104.7 | Z13: 104.2 | AA13: 105 | AB13: 102.9 | AC13: 104.8 | AD13: 106.1
... A373: Rural+Urban | B373: 2023 | C373: May | D373: 173.7 | E373: 214.3 | F373: 173.2 | G373: 179.5 | H373: 170 | I373: 172.2 | J373: 161 | K373: 175.6 | L373: 122.7 | M373: 218 | N373: 173.4 | O373: 194.2 | P373: 179.1 | Q373: 201 | R373: 187.3 | S373: 179.7 | T373: 186.2 | U373: 175.6 | V373: 182.8 | W373: 175.2 | X373: 185.7 | Y373: 164.8 | Z373: 171.2 | AA373: 177.1 | AB373: 185.2 | AC373: 175.7 | AD373: 179.1

Sheet Buckets
A1: Sector | B1: Year | C1: Month | D1: Food & Beverages | E1: Energy | F1: Transportation | G1: Education | H1: Health and Personal care | I1: Housing and Household | J1: Clothing and Footwear | K1: Recreation and miscellaneous | L1: General index
A2: Rural | B2: 2013 | C2: January | D2: =SUM(Table13[[#This Row],[Cereals and products]:[Food and beverages]]) -> 1371.7 | E2: 105.5 | F2: 103.3 | G2: 103.8 | H2: =SUM('Working Data'!X2,'Working Data'!AB2) -> 208.7 | I2: =SUM('Working Data'!U2,'Working Data'!W2) -> 205.1 | J2: =SUM('Working Data'!R2,'Working Data'!S2,'Working Data'!T2) -> 318.7 | K2: =SUM('Working Data'!AC2,'Working Data'!Z2,'Working Data'!Q2) -> 312.5 | L2: 105.1
A3: Urban | B3: 2013 | C3: January | D3: =SUM(Table13[[#This Row],[Cereals and products]:[Food and beverages]]) -> 1376.4 | E3: 105.4 | F3: 103.2 | G3: 103.5 | H3: =SUM('Working Data'!X3,'Working Data'!AB3) -> 208.4 | I3: =SUM('Working Data'!U3,'Working Data'!W3) -> 205.1 | J3: =SUM('Working Data'!R3,'Working Data'!S3,'Working Data'!T3) -> 316.7 | K3: =SUM('Working Data'!AC3,'Working Data'!Z3,'Working Data'!Q3) -> 311.8 | L3: 104
A4: Rural+Urban | B4: 2013 | C4: January | D4: =SUM(Table13[[#This Row],[Cereals and products]:[Food and beverages]]) -> 1373.3 | E4: 105.5 | F4: 103.2 | G4: 103.6 | H4: =SUM('Working Data'!X4,'Working Data'!AB4) -> 208.5 | I4: =SUM('Working Data'!U4,'Working Data'!W4) -> 205.1 | J4: =SUM('Working Data'!R4,'Working Data'!S4,'Working Data'!T4) -> 318 | K4: =SUM('Working Data'!AC4,'Working Data'!Z4,'Working Data'!Q4) -> 312.1 | L4: 104.6
A5: Rural | B5: 2013 | C5: February | D5: =SUM(Table13[[#This Row],[Cereals and products]:[Food and beverages]]) -> 1380.4 | E5: 106.2 | F5: 103.9 | G5: 104.1 | H5: =SUM('Working Data'!X5,'Working Data'!AB5) -> 209 | I5: =SUM('Working Data'!U5,'Working Data'!W5) -> 205.6 | J5: =SUM('Working Data'!R5,'Working Data'!S5,'Working Data'!T5) -> 320.4 | K5: =SUM('Working Data'!AC5,'Working Data'!Z5,'Working Data'!Q5) -> 314 | L5: 105.8
A6: Urban | B6: 2013 | C6: February | D6: =SUM(Table13[[#This Row],[Cereals and products]:[Food and beverages]]) -> 1390.6 | E6: 105.7 | F6: 104.4 | G6: 103.7 | H6: =SUM('Working Data'!X6,'Working Data'!AB6) -> 209 | I6: =SUM('Working Data'!U6,'Working Data'!W6) -> 205.6 | J6: =SUM('Working Data'!R6,'Working Data'!S6,'Working Data'!T6) -> 318.5 | K6: =SUM('Working Data'!AC6,'Working Data'!Z6,'Working Data'!Q6) -> 313.6 | L6: 104.7
A7: Rural+Urban | B7: 2013 | C7: February | D7: =SUM(Table13[[#This Row],[Cereals and products]:[Food and beverages]]) -> 1384.2 | E7: 106 | F7: 104.2 | G7: 103.9 | H7: =SUM('Working Data'!X7,'Working Data'!AB7) -> 209 | I7: =SUM('Working Data'!U7,'Working Data'!W7) -> 205.6 | J7: =SUM('Working Data'!R7,'Working Data'!S7,'Working Data'!T7) -> 319.7 | K7: =SUM('Working Data'!AC7,'Working Data'!Z7,'Working Data'!Q7) -> 313.7 | L7: 105.3
A8: Rural | B8: 2013 | C8: March | D8: =SUM(Table13[[#This Row],[Cereals and products]:[Food and beverages]]) -> 1382.2 | E8: 106.1 | F8: 104.6 | G8: 104.3 | H8: =SUM('Working Data'!X8,'Working Data'!AB8) -> 209 | I8: =SUM('Working Data'!U8,'Working Data'!W8) -> 206 | J8: =SUM('Working Data'!R8,'Working Data'!S8,'Working Data'!T8) -> 321.9 | K8: =SUM('Working Data'!AC8,'Working Data'!Z8,'Working Data'!Q8) -> 315.1 | L8: 106
A9: Urban | B9: 2013 | C9: March | D9: =SUM(Table13[[#This Row],[Cereals and products]:[Food and beverages]]) -> 1386.8 | E9: 106 | F9: 105.5 | G9: 103.8 | H9: =SUM('Working Data'!X9,'Working Data'!AB9) -> 209.4 | I9: =SUM('Working Data'!U9,'Working Data'!W9) -> 206.1 | J9: =SUM('Working Data'!R9,'Working Data'!S9,'Working Data'!T9) -> 320.2 | K9: =SUM('Working Data'!AC9,'Working Data'!Z9,'Working Data'!Q9) -> 315.2 | L9: 105
A10: Rural+Urban | B10: 2013 | C10: March | D10: =SUM(Table13[[#This Row],[Cereals and products]:[Food and beverages]]) -> 1384 | E10: 106.1 | F10: 105.1 | G10: 104 | H10: =SUM('Working Data'!X10,'Working Data'!AB10) -> 209.2 | I10: =SUM('Working Data'!U10,'Working Data'!W10) -> 206 | J10: =SUM('Working Data'!R10,'Working Data'!S10,'Working Data'!T10) -> 321.2 | K10: =SUM('Working Data'!AC10,'Working Data'!Z10,'Working Data'!Q10) -> 315 | L10: 105.5
A11: Rural | B11: 2013 | C11: April | D11: =SUM(Table13[[#This Row],[Cereals and products]:[Food and beverages]]) -> 1385.8 | E11: 106.5 | F11: 104.4 | G11: 104.8 | H11: =SUM('Working Data'!X11,'Working Data'!AB11) -> 207.8 | I11: =SUM('Working Data'!U11,'Working Data'!W11) -> 206.6 | J11: =SUM('Working Data'!R11,'Working Data'!S11,'Working Data'!T11) -> 323.5 | K11: =SUM('Working Data'!AC11,'Working Data'!Z11,'Working Data'!Q11) -> 316.2 | L11: 106.4
A12: Urban | B12: 2013 | C12: April | D12: =SUM(Table13[[#This Row],[Cereals and products]:[Food and beverages]]) -> 1397.7 | E12: 106.4 | F12: 105 | G12: 105.2 | H12: =SUM('Working Data'!X12,'Working Data'!AB12) -> 208.9 | I12: =SUM('Working Data'!U12,'Working Data'!W12) -> 207 | J12: =SUM('Working Data'!R12,'Working Data'!S12,'Working Data'!T12) -> 322 | K12: =SUM('Working Data'!AC12,'Working Data'!Z12,'Working Data'!Q12) -> 317.6 | L12: 105.7
A13: Rural+Urban | B13: 2013 | C13: April | D13: =SUM(Table13[[#This Row],[Cereals and products]:[Food and beverages]]) -> 1390.2 | E13: 106.5 | F13: 104.7 | G13: 105 | H13: =SUM('Working Data'!X13,'Working Data'!AB13) -> 208.2 | I13: =SUM('Working Data'!U13,'Working Data'!W13) -> 206.8 | J13: =SUM('Working Data'!R13,'Working Data'!S13,'Working Data'!T13) -> 322.9 | K13: =SUM('Working Data'!AC13,'Working Data'!Z13,'Working Data'!Q13) -> 316.5 | L13: 106.1
... A373: Rural+Urban | B373: 2023 | C373: May | D373: =SUM(Table13[[#This Row],[Cereals and products]:[Food and beverages]]) -> 2306.9 | E373: 182.8 | F373: 164.8 | G373: 177.1 | H373: =SUM('Working Data'!X373,'Working Data'!AB373) -> 370.9 | I373: =SUM('Working Data'!U373,'Working Data'!W373) -> 350.8 | J373: =SUM('Working Data'!R373,'Working Data'!S373,'Working Data'!T373) -> 553.2 | K373: =SUM('Working Data'!AC373,'Working Data'!Z373,'Working Data'!Q373) -> 547.9 | L373: 179.1

Sheet Problem statement 1
B2: Year | C2: Month | D2: Broader categories | E2: Sub-categories | F2: Rural | G2: Urban | H2: Rural + Urban
B3: 2023 | C3: May | D3: Food & Beverages | E3: Cereals and products | F3: =HLOOKUP(E3,Table13[[#All],[Cereals and products]:[General index]],371,0) -> 173.2 | G3: =HLOOKUP(E3,Table13[[#All],[Cereals and products]:[General index]],372,0) -> 174.7 | H3: =HLOOKUP(E3,Table13[[#All],[Cereals and products]:[General index]],373,0) -> 173.7
B4: 2023 | C4: May | D4: Food & Beverages | E4: Meat and fish | F4: =HLOOKUP(E4,Table13[[#All],[Cereals and products]:[General index]],371,0) -> 211.5 | G4: =HLOOKUP(E4,Table13[[#All],[Cereals and products]:[General index]],372,0) -> 219.4 | H4: =HLOOKUP(E4,Table13[[#All],[Cereals and products]:[General index]],373,0) -> 214.3
B5: 2023 | C5: May | D5: Food & Beverages | E5: Egg | F5: =HLOOKUP(E5,Table13[[#All],[Cereals and products]:[General index]],371,0) -> 171 | G5: =HLOOKUP(E5,Table13[[#All],[Cereals and products]:[General index]],372,0) -> 176.7 | H5: =HLOOKUP(E5,Table13[[#All],[Cereals and products]:[General index]],373,0) -> 173.2
B6: 2023 | C6: May | D6: Food & Beverages | E6: Milk and products | F6: =HLOOKUP(E6,Table13[[#All],[Cereals and products]:[General index]],371,0) -> 179.6 | G6: =HLOOKUP(E6,Table13[[#All],[Cereals and products]:[General index]],372,0) -> 179.4 | H6: =HLOOKUP(E6,Table13[[#All],[Cereals and products]:[General index]],373,0) -> 179.5
B7: 2023 | C7: May | D7: Food & Beverages | E7: Oils and fats | F7: =HLOOKUP(E7,Table13[[#All],[Cereals and products]:[General index]],371,0) -> 173.3 | G7: =HLOOKUP(E7,Table13[[#All],[Cereals and products]:[General index]],372,0) -> 164.4 | H7: =HLOOKUP(E7,Table13[[#All],[Cereals and products]:[General index]],373,0) -> 170
B8: 2023 | C8: May | D8: Food & Beverages | E8: Fruits | F8: =HLOOKUP(E8,Table13[[#All],[Cereals and products]:[General index]],371,0) -> 169 | G8: =HLOOKUP(E8,Table13[[#All],[Cereals and products]:[General index]],372,0) -> 175.8 | H8: =HLOOKUP(E8,Table13[[#All],[Cereals and products]:[General index]],373,0) -> 172.2
B9: 2023 | C9: May | D9: Food & Beverages | E9: Vegetables | F9: =HLOOKUP(E9,Table13[[#All],[Cereals and products]:[General index]],371,0) -> 148.7 | G9: =HLOOKUP(E9,Table13[[#All],[Cereals and products]:[General index]],372,0) -> 185 | H9: =HLOOKUP(E9,Table13[[#All],[Cereals and products]:[General index]],373,0) -> 161
B10: 2023 | C10: May | D10: Food & Beverages | E10: Pulses and products | F10: =HLOOKUP(E10,Table13[[#All],[Cereals and products]:[General index]],371,0) -> 174.9 | G10: =HLOOKUP(E10,Table13[[#All],[Cereals and products]:[General index]],372,0) -> 176.9 | H10: =HLOOKUP(E10,Table13[[#All],[Cereals and products]:[General index]],373,0) -> 175.6
B11: 2023 | C11: May | D11: Food & Beverages | E11: Sugar and Confectionery | F11: =HLOOKUP(E11,Table13[[#All],[Cereals and products]:[General index]],371,0) -> 121.9 | G11: =HLOOKUP(E11,Table13[[#All],[Cereals and products]:[General index]],372,0) -> 124.2 | H11: =HLOOKUP(E11,Table13[[#All],[Cereals and products]:[General index]],373,0) -> 122.7 | J11: Row Labels | K11: Sum of Rural + Urban
B12: 2023 | C12: May | D12: Food & Beverages | E12: Spices | F12: =HLOOKUP(E12,Table13[[#All],[Cereals and products]:[General index]],371,0) -> 221 | G12: =HLOOKUP(E12,Table13[[#All],[Cereals and products]:[General index]],372,0) -> 211.9 | H12: =HLOOKUP(E12,Table13[[#All],[Cereals and products]:[General index]],373,0) -> 218 | J12: Food & Beverages | K12: 0.49563854
B13: 2023 | C13: May | D13: Food & Beverages | E13: Non-alcoholic beverages | F13: =HLOOKUP(E13,Table13[[#All],[Cereals and products]:[General index]],371,0) -> 178.7 | G13: =HLOOKUP(E13,Table13[[#All],[Cereals and products]:[General index]],372,0) -> 165.9 | H13: =HLOOKUP(E13,Table13[[#All],[Cereals and products]:[General index]],373,0) -> 173.4 | J13: Clothing and Footwear | K13: 0.11885528
B14: 2023 | C14: May | D14: Food & Beverages | E14: Prepared meals, snacks, sweets etc. | F14: =HLOOKUP(E14,Table13[[#All],[Cereals and products]:[General index]],371,0) -> 191.1 | G14: =HLOOKUP(E14,Table13[[#All],[Cereals and products]:[General index]],372,0) -> 197.7 | H14: =HLOOKUP(E14,Table13[[#All],[Cereals and products]:[General index]],373,0) -> 194.2 | J14: Recreation and miscellaneous | K14: 0.11771657
B15: 2023 | C15: May | D15: Food & Beverages | E15: Food and beverages | F15: =HLOOKUP(E15,Table13[[#All],[Cereals and products]:[General index]],371,0) -> 176.8 | G15: =HLOOKUP(E15,Table13[[#All],[Cereals and products]:[General index]],372,0) -> 183.1 | H15: =HLOOKUP(E15,Table13[[#All],[Cereals and products]:[General index]],373,0) -> 179.1 | J15: Health and Personal care | K15: 0.079688037
B16: 2023 | C16: May | D16: Energy | E16: Fuel and light | F16: =HLOOKUP(E16,Table13[[#All],[Cereals and products]:[General index]],371,0) -> 182.5 | G16: =HLOOKUP(E16,Table13[[#All],[Cereals and products]:[General index]],372,0) -> 183.4 | H16: =HLOOKUP(E16,Table13[[#All],[Cereals and products]:[General index]],373,0) -> 182.8 | J16: Housing and Household | K16: 0.075369543
B17: 2023 | C17: May | D17: Transportation | E17: Transport and communication | F17: =HLOOKUP(E17,Table13[[#All],[Cereals and products]:[General index]],371,0) -> 169.7 | G17: =HLOOKUP(E17,Table13[[#All],[Cereals and products]:[General index]],372,0) -> 160.4 | H17: =HLOOKUP(E17,Table13[[#All],[Cereals and products]:[General index]],373,0) -> 164.8 | J17: Energy | K17: 0.039274665
B18: 2023 | C18: May | D18: Education | E18: Education | F18: =HLOOKUP(E18,Table13[[#All],[Cereals and products]:[General index]],371,0) -> 180.3 | G18: =HLOOKUP(E18,Table13[[#All],[Cereals and products]:[General index]],372,0) -> 174.8 | H18: =HLOOKUP(E18,Table13[[#All],[Cereals and products]:[General index]],373,0) -> 177.1 | J18: Education | K18: 0.038050017
B19: 2023 | C19: May | D19: Health and Personal care | E19: Health | F19: =HLOOKUP(E19,Table13[[#All],[Cereals and products]:[General index]],371,0) -> 187.8 | G19: =HLOOKUP(E19,Table13[[#All],[Cereals and products]:[General index]],372,0) -> 182.2 | H19: =HLOOKUP(E19,Table13[[#All],[Cereals and products]:[General index]],373,0) -> 185.7 | J19: Transportation | K19: 0.035407356
B20: 2023 | C20: May | D20: Health and Personal care | E20: Personal care and effects | F20: =HLOOKUP(E20,Table13[[#All],[Cereals and products]:[General index]],371,0) -> 184.9 | G20: =HLOOKUP(E20,Table13[[#All],[Cereals and products]:[General index]],372,0) -> 185.6 | H20: =HLOOKUP(E20,Table13[[#All],[Cereals and products]:[General index]],373,0) -> 185.2 | J20: Grand Total | K20: 1
B21: 2023 | C21: May | D21: Housing and Household | E21: Housing | F21: =HLOOKUP(E21,Table13[[#All],[Cereals and products]:[General index]],371,0) -> 175.6 | G21: =HLOOKUP(E21,Table13[[#All],[Cereals and products]:[General index]],372,0) -> 175.6 | H21: =HLOOKUP(E21,Table13[[#All],[Cereals and products]:[General index]],373,0) -> 175.6
B22: 2023 | C22: May | D22: Housing and Household | E22: Household goods and services | F22: =HLOOKUP(E22,Table13[[#All],[Cereals and products]:[General index]],371,0) -> 179.8 | G22: =HLOOKUP(E22,Table13[[#All],[Cereals and products]:[General index]],372,0) -> 170.1 | H22: =HLOOKUP(E22,Table13[[#All],[Cereals and products]:[General index]],373,0) -> 175.2 | J22: Tasks:
B23: 2023 | C23: May | D23: Clothing and Footwear | E23: Clothing | F23: =HLOOKUP(E23,Table13[[#All],[Cereals and products]:[General index]],371,0) -> 191.2 | G23: =HLOOKUP(E23,Table13[[#All],[Cereals and products]:[General index]],372,0) -> 181.3 | H23: =HLOOKUP(E23,Table13[[#All],[Cereals and products]:[General index]],373,0) -> 187.3 | J23: 1. Which broader category has the highest contribution towards CPI calculation?
B24: 2023 | C24: May | D24: Clothing and Footwear | E24: Footwear | F24: =HLOOKUP(E24,Table13[[#All],[Cereals and products]:[General index]],371,0) -> 187.9 | G24: =HLOOKUP(E24,Table13[[#All],[Cereals and products]:[General index]],372,0) -> 168.1 | H24: =HLOOKUP(E24,Table13[[#All],[Cereals and products]:[General index]],373,0) -> 179.7 | J24: Food & Beverage
B25: 2023 | C25: May | D25: Clothing and Footwear | E25: Clothing and footwear | F25: =HLOOKUP(E25,Table13[[#All],[Cereals and products]:[General index]],371,0) -> 190.8 | G25: =HLOOKUP(E25,Table13[[#All],[Cereals and products]:[General index]],372,0) -> 179.3 | H25: =HLOOKUP(E25,Table13[[#All],[Cereals and products]:[General index]],373,0) -> 186.2 | J25: 2. Contribution is calculated by evaluating the underlying index values for broader categories, and the total should add up to 100% when all broader categories are added.
B26: 2023 | C26: May | D26: Recreation and miscellaneous | E26: Pan, tobacco and intoxicants | F26: =HLOOKUP(E26,Table13[[#All],[Cereals and products]:[General index]],371,0) -> 199.9 | G26: =HLOOKUP(E26,Table13[[#All],[Cereals and products]:[General index]],372,0) -> 204.2 | H26: =HLOOKUP(E26,Table13[[#All],[Cereals and products]:[General index]],373,0) -> 201
B27: 2023 | C27: May | D27: Recreation and miscellaneous | E27: Recreation and amusement | F27: =HLOOKUP(E27,Table13[[#All],[Cereals and products]:[General index]],371,0) -> 173.8 | G27: =HLOOKUP(E27,Table13[[#All],[Cereals and products]:[General index]],372,0) -> 169.2 | H27: =HLOOKUP(E27,Table13[[#All],[Cereals and products]:[General index]],373,0) -> 171.2 | J27: Done
B28: 2023 | C28: May | D28: Recreation and miscellaneous | E28: Miscellaneous | F28: =HLOOKUP(E28,Table13[[#All],[Cereals and products]:[General index]],371,0) -> 179.5 | G28: =HLOOKUP(E28,Table13[[#All],[Cereals and products]:[General index]],372,0) -> 171.6 | H28: =HLOOKUP(E28,Table13[[#All],[Cereals and products]:[General index]],373,0) -> 175.7

Sheet Problem statement 2
B2: Sector | C2: Rural+Urban
B4: Sum of General index | C4: Column Labels
B5: Row Labels | C5: January | D5: December
B6: 2016 | C6: 126.3 | D6: 130.4
B7: 2017 | C7: 130.3 | D7: 137.2
B8: 2018 | C8: 136.9 | D8: 140.1
B9: 2019 | C9: 139.6 | D9: 150.4
B10: 2020 | C10: 150.2 | D10: 158.9
B11: 2021 | C11: 157.3 | D11: 166.2
B12: 2022 | C12: 165.7 | D12: 175.7
B13: 2023 | C13: 176.5
B14: Grand Total | C14: 1182.8 | D14: 1058.9
B16: Row Labels | C16: January | D16: December | E16: Y-o-Y Inflation Rate
B17: 2016 | C17: 126.3 | D17: 130.4 | E17: =(D17-C17)/C17 -> 0.032462391
B18: 2017 | C18: 130.3 | D18: 137.2 | E18: =(D18-C18)/C18 -> 0.05295472
B19: 2018 | C19: 136.9 | D19: 140.1 | E19: =(D19-C19)/C19 -> 0.023374726
B20: 2019 | C20: 139.6 | D20: 150.4 | E20: =(D20-C20)/C20 -> 0.077363897
B21: 2020 | C21: 150.2 | D21: 158.9 | E21: =(D21-C21)/C21 -> 0.05792277
B22: 2021 | C22: 157.3 | D22: 166.2 | E22: =(D22-C22)/C22 -> 0.056579784
B23: 2022 | C23: 165.7 | D23: 175.7 | E23: =(D23-C23)/C23 -> 0.06035003
B24: 2023 | C24: 176.5
B26: Formula Used for Annual Inflation Rate:- ((CPI at the end of the year-CPI at the start of year)/CPI at start of year )*100
B28: Insights:
B29: 2019 had the highest Y-o-Y inflation rate (7.7%) between 2017 and 2022.
B30: 1. Sharp increases in vegetable and onion prices during mid to late 2019.Unseasonal rainfall and floods affected crop yields, particularly onions and tomatoes.
B31: 2. The primary cause was food inflation driven by poor agricultural output and weather disruptions.
B32: 3. Additional pressure from global oil prices, currency depreciation, and a low base effect compounded the inflation spike.

Sheet Problem statement 3
B11: Sector | C11: Year | D11: Month | E11: Food & Beverages | F11: M-o-M Inflation Rate
B12: Rural+Urban | C12: 2022 | D12: June | E12: 2261.9
B13: Rural+Urban | C13: 2022 | D13: July | E13: 2266.3 | F13: =(E13-E12)/E13 -> 0.0019414905
B14: Rural+Urban | C14: 2022 | D14: August | E14: 2269.2 | F14: =(E14-E13)/E14 -> 0.0012779834
B15: Rural+Urban | C15: 2022 | D15: September | E15: 2280.9 | F15: =(E15-E14)/E15 -> 0.0051295541
B16: Rural+Urban | C16: 2022 | D16: October | E16: 2297.3 | F16: =(E16-E15)/E16 -> 0.0071388151
B17: Rural+Urban | C17: 2022 | D17: November | E17: 2296.8 | F17: =(E17-E16)/E17 -> -0.00021769418
B18: Rural+Urban | C18: 2022 | D18: December | E18: 2283.4 | F18: =(E18-E17)/E18 -> -0.0058684418
B19: Rural+Urban | C19: 2023 | D19: January | E19: 2292.7 | F19: =(E19-E18)/E19 -> 0.0040563528
B20: Rural+Urban | C20: 2023 | D20: February | E20: 2279.1 | F20: =(E20-E19)/E20 -> -0.0059672678
B21: Rural+Urban | C21: 2023 | D21: March | E21: 2279.2 | F21: =(E21-E20)/E21 -> 4.3875044e-05
B22: Rural+Urban | C22: 2023 | D22: April | E22: 2289.6 | F22: =(E22-E21)/E22 -> 0.0045422781
B23: Rural+Urban | C23: 2023 | D23: May | E23: 2306.9 | F23: =(E23-E22)/E23 -> 0.0074992414
B25: Task -
B26: 1. Identifying the highest & lowest MoM food inflation
B27: Highest: May 2023 (0.75%)
B28: Lowest: February 2023 (-0.60%)
B29: 2. Analyzing absolute changes over the 12-month period
B30: =(E23-E12)/E12 -> 0.019894779
B31: 3. Biggest contributor
B32: Spices
B34: Sector | C34: Year | D34: Month | E34: Cereals and products | F34: Meat and fish | G34: Egg | H34: Milk and products | I34: Oils and fats | J34: Fruits | K34: Vegetables | L34: Pulses and products | M34: Sugar and Confectionery | N34: Spices | O34: Non-alcoholic beverages | P34: Prepared meals, snacks, sweets etc. | Q34: Food and beverages
B35: Rural+Urban | C35: 2022 | D35: June | E35: 155 | F35: 219.4 | G35: 170.8 | H35: 165.8 | I35: 200.9 | J35: 169.7 | K35: 182.3 | L35: 164.3 | M35: 119.9 | N35: 187.1 | O35: 167.9 | P35: 183.9 | Q35: 174.9
B36: Rural+Urban | C36: 2022 | D36: July | E36: 156.5 | F36: 213 | G36: 175.2 | H36: 166.6 | I36: 195.8 | J36: 174.2 | K36: 182.1 | L36: 164.3 | M36: 120 | N36: 190 | O36: 168.4 | P36: 185.2 | Q36: 175
B37: Rural+Urban | C37: 2022 | D37: August | E37: 160.3 | F37: 206.5 | G37: 169.2 | H37: 168.1 | I37: 192.4 | J37: 172.9 | K37: 186.7 | L37: 167.2 | M37: 120.9 | N37: 193.6 | O37: 168.8 | P37: 186.3 | Q37: 176.3
B38: Rural+Urban | C38: 2022 | D38: September | E38: 163.5 | F38: 209.2 | G38: 169.7 | H38: 169.7 | I38: 188.7 | J38: 165.7 | K38: 191.8 | L38: 169.1 | M38: 121.6 | N38: 197.3 | O38: 169.4 | P38: 187.4 | Q38: 177.8
B39: Rural+Urban | C39: 2022 | D39: October | E39: 165.2 | F39: 210.9 | G39: 170.9 | H39: 170.9 | I39: 186.5 | J39: 163.8 | K39: 199.7 | L39: 169.8 | M39: 121.9 | N39: 199.9 | O39: 169.9 | P39: 188.3 | Q39: 179.6
B40: Rural+Urban | C40: 2022 | D40: November | E40: 167.4 | F40: 209.4 | G40: 181.4 | H40: 172.3 | I40: 188.9 | J40: 160.7 | K40: 183.1 | L40: 170.5 | M40: 122.1 | N40: 202.8 | O40: 170.4 | P40: 189.5 | Q40: 178.3
B41: Rural+Urban | C41: 2022 | D41: December | E41: 169.2 | F41: 209 | G41: 190.2 | H41: 173.6 | I41: 188.5 | J41: 158 | K41: 159.9 | L41: 170.8 | M41: 121.8 | N41: 205.2 | O41: 171 | P41: 190.3 | Q41: 175.9
B42: Rural+Urban | C42: 2023 | D42: January | E42: 173.8 | F42: 210.7 | G42: 194.5 | H42: 174.6 | I42: 187.2 | J42: 158.3 | K42: 153.9 | L42: 170.9 | M42: 121.1 | N42: 208.4 | O42: 171.4 | P42: 191.2 | Q42: 176.7
B43: Rural+Urban | C43: 2023 | D43: February | E43: 174.4 | F43: 207.7 | G43: 175.2 | H43: 177.3 | I43: 179.3 | J43: 169.5 | K43: 152.7 | L43: 171 | M43: 120 | N43: 209.7 | O43: 172.3 | P43: 193 | Q43: 177
B44: Rural+Urban | C44: 2023 | D44: March | E44: 174.4 | F44: 207.7 | G44: 175.2 | H44: 177.3 | I44: 179.2 | J44: 169.5 | K44: 152.8 | L44: 171.1 | M44: 120 | N44: 209.7 | O44: 172.3 | P44: 193 | Q44: 177
B45: Rural+Urban | C45: 2023 | D45: April | E45: 173.8 | F45: 209.3 | G45: 169.6 | H45: 178.4 | I45: 174.9 | J45: 176.3 | K45: 155.4 | L45: 173.4 | M45: 121.3 | N45: 212.9 | O45: 172.9 | P45: 193.5 | Q45: 177.9
B46: Rural+Urban | C46: 2023 | D46: May | E46: 173.7 | F46: 214.3 | G46: 173.2 | H46: 179.5 | I46: 170 | J46: 172.2 | K46: 161 | L46: 175.6 | M46: 122.7 | N46: 218 | O46: 173.4 | P46: 194.2 | Q46: 179.1
B47: Inflation for each category | E47: =(E46-E35)/E35 -> 0.12064516 | F47: =(F46-F35)/F35 -> -0.023245214 | G47: =(G46-G35)/G35 -> 0.014051522 | H47: =(H46-H35)/H35 -> 0.082629674 | I47: =(I46-I35)/I35 -> -0.15380786 | J47: =(J46-J35)/J35 -> 0.01473188 | K47: =(K46-K35)/K35 -> -0.11684037 | L47: =(L46-L35)/L35 -> 0.068776628 | ... Q47: =(Q46-Q35)/Q35 -> 0.024013722

Sheet Problem statement 4
B2: Sector | C2: Year | D2: Month | E2: Food & Beverages | F2: Health and Personal care | G2: Essential | H2: Food Inflation | I2: Health Inflation | J2: Essential Inflation | K2: Period
B3: Rural+Urban | C3: 2019 | D3: January | E3: 1753.4 | F3: 277.9 | G3: =SUM('Working Data'!W220,'Working Data'!V220,'Working Data'!T220,'Working Data'!Q220) -> 592.7
B4: Rural+Urban | C4: 2019 | D4: February | E4: 1757.1 | F4: 279.7 | G4: =SUM('Working Data'!W221,'Working Data'!V221,'Working Data'!T221,'Working Data'!Q221) -> 608.1 | H4: =(Table11[[#This Row],[Food & Beverages]]-E3)/E3 -> 0.0021101859 | I4: =(Table11[[#This Row],[Health and Personal care]]-F3)/F3 -> 0.0064771501 | J4: =(Table11[[#This Row],[Essential]]-G3)/G3 -> 0.025982791 | K4: Before Covid
B5: Rural+Urban | C5: 2019 | D5: March | E5: 1762.9 | F5: 279.6 | G5: =SUM('Working Data'!W222,'Working Data'!V222,'Working Data'!T222,'Working Data'!Q222) -> 570 | H5: =(Table11[[#This Row],[Food & Beverages]]-E4)/E4 -> 0.0033008935 | I5: =(Table11[[#This Row],[Health and Personal care]]-F4)/F4 -> -0.00035752592 | J5: =(Table11[[#This Row],[Essential]]-G4)/G4 -> -0.062654169 | K5: Before Covid
B6: Rural+Urban | C6: 2019 | D6: May | E6: 1791.9 | F6: 280.3 | G6: =SUM('Working Data'!W223,'Working Data'!V223,'Working Data'!T223,'Working Data'!Q223) -> 592 | H6: =(Table11[[#This Row],[Food & Beverages]]-E5)/E5 -> 0.016450167 | I6: =(Table11[[#This Row],[Health and Personal care]]-F5)/F5 -> 0.0025035765 | J6: =(Table11[[#This Row],[Essential]]-G5)/G5 -> 0.038596491 | K6: Before Covid
B7: Rural+Urban | C7: 2019 | D7: June | E7: 1814.1 | F7: 281.7 | G7: =SUM('Working Data'!W224,'Working Data'!V224,'Working Data'!T224,'Working Data'!Q224) -> 609.4 | H7: =(Table11[[#This Row],[Food & Beverages]]-E6)/E6 -> 0.012389084 | I7: =(Table11[[#This Row],[Health and Personal care]]-F6)/F6 -> 0.0049946486 | J7: =(Table11[[#This Row],[Essential]]-G6)/G6 -> 0.029391892 | K7: Before Covid
B8: Rural+Urban | C8: 2019 | D8: July | E8: 1837.5 | F8: 283.6 | G8: =SUM('Working Data'!W225,'Working Data'!V225,'Working Data'!T225,'Working Data'!Q225) -> 572.5 | H8: =(Table11[[#This Row],[Food & Beverages]]-E7)/E7 -> 0.012898958 | I8: =(Table11[[#This Row],[Health and Personal care]]-F7)/F7 -> 0.0067447639 | J8: =(Table11[[#This Row],[Essential]]-G7)/G7 -> -0.060551362 | K8: Before Covid
B9: Rural+Urban | C9: 2019 | D9: August | E9: 1846.5 | F9: 286.9 | G9: =SUM('Working Data'!W226,'Working Data'!V226,'Working Data'!T226,'Working Data'!Q226) -> 593.7 | H9: =(Table11[[#This Row],[Food & Beverages]]-E8)/E8 -> 0.0048979592 | I9: =(Table11[[#This Row],[Health and Personal care]]-F8)/F8 -> 0.011636107 | J9: =(Table11[[#This Row],[Essential]]-G8)/G8 -> 0.037030568 | K9: Before Covid
B10: Rural+Urban | C10: 2019 | D10: September | E10: 1857.7 | F10: 288.7 | G10: =SUM('Working Data'!W227,'Working Data'!V227,'Working Data'!T227,'Working Data'!Q227) -> 610.4 | H10: =(Table11[[#This Row],[Food & Beverages]]-E9)/E9 -> 0.0060655294 | I10: =(Table11[[#This Row],[Health and Personal care]]-F9)/F9 -> 0.0062739631 | J10: =(Table11[[#This Row],[Essential]]-G9)/G9 -> 0.028128685 | K10: Before Covid
B11: Rural+Urban | C11: 2019 | D11: October | E11: 1885.6 | F11: 289.4 | G11: =SUM('Working Data'!W228,'Working Data'!V228,'Working Data'!T228,'Working Data'!Q228) -> 575 | H11: =(Table11[[#This Row],[Food & Beverages]]-E10)/E10 -> 0.015018571 | I11: =(Table11[[#This Row],[Health and Personal care]]-F10)/F10 -> 0.0024246623 | J11: =(Table11[[#This Row],[Essential]]-G10)/G10 -> -0.057994758 | K11: Before Covid | M11: Essentials:
B12: Rural+Urban | C12: 2019 | D12: November | E12: 1910.9 | F12: 290.2 | G12: =SUM('Working Data'!W229,'Working Data'!V229,'Working Data'!T229,'Working Data'!Q229) -> 595.4 | H12: =(Table11[[#This Row],[Food & Beverages]]-E11)/E11 -> 0.01341748 | I12: =(Table11[[#This Row],[Health and Personal care]]-F11)/F11 -> 0.00276434 | J12: =(Table11[[#This Row],[Essential]]-G11)/G11 -> 0.035478261 | K12: Before Covid | M12: Household goods and services Clothing and footwear Fuel and light Pan, tobacco and intoxicants
B13: Rural+Urban | C13: 2019 | D13: December | E13: 1946.1 | F13: 290.8 | G13: =SUM('Working Data'!W230,'Working Data'!V230,'Working Data'!T230,'Working Data'!Q230) -> 612.3 | H13: =(Table11[[#This Row],[Food & Beverages]]-E12)/E12 -> 0.018420639 | I13: =(Table11[[#This Row],[Health and Personal care]]-F12)/F12 -> 0.0020675396 | J13: =(Table11[[#This Row],[Essential]]-G12)/G12 -> 0.028384279 | K13: Before Covid
B14: Rural+Urban | C14: 2020 | D14: January | E14: 1940.4 | F14: 293.5 | G14: =SUM('Working Data'!W231,'Working Data'!V231,'Working Data'!T231,'Working Data'!Q231) -> 577 | H14: =(Table11[[#This Row],[Food & Beverages]]-E13)/E13 -> -0.0029289348 | I14: =(Table11[[#This Row],[Health and Personal care]]-F13)/F13 -> 0.0092847318 | J14: =(Table11[[#This Row],[Essential]]-G13)/G13 -> -0.057651478 | K14: Before Covid
B15: Rural+Urban | C15: 2020 | D15: February | E15: 1911.6 | F15: 295.1 | G15: =SUM('Working Data'!W232,'Working Data'!V232,'Working Data'!T232,'Working Data'!Q232) -> 597.3 | H15: =(Table11[[#This Row],[Food & Beverages]]-E14)/E14 -> -0.014842301 | I15: =(Table11[[#This Row],[Health and Personal care]]-F14)/F14 -> 0.005451448 | J15: =(Table11[[#This Row],[Essential]]-G14)/G14 -> 0.035181976 | K15: Before Covid
B16: Rural+Urban | C16: 2020 | D16: March | E16: 1895.4 | F16: 297.5 | G16: =SUM('Working Data'!W233,'Working Data'!V233,'Working Data'!T233,'Working Data'!Q233) -> 612.2 | H16: =(Table11[[#This Row],[Food & Beverages]]-E15)/E15 -> -0.0084745763 | I16: =(Table11[[#This Row],[Health and Personal care]]-F15)/F15 -> 0.0081328363 | J16: =(Table11[[#This Row],[Essential]]-G15)/G15 -> 0.024945588 | K16: Covid Onset
B17: Rural+Urban | C17: 2020 | D17: April | E17: 1949.35 | F17: 295.01667 | G17: =SUM('Working Data'!W234,'Working Data'!V234,'Working Data'!T234,'Working Data'!Q234) -> 574.6 | H17: =(Table11[[#This Row],[Food & Beverages]]-E16)/E16 -> 0.028463649 | I17: =(Table11[[#This Row],[Health and Personal care]]-F16)/F16 -> -0.0083473389 | J17: =(Table11[[#This Row],[Essential]]-G16)/G16 -> -0.061417837 | K17: After Covid | M17: Insights Before March 2020 (Jan 2019 – Mar 2020):
B18: Rural+Urban | C18: 2020 | D18: May | E18: 1923.7833 | F18: 295.83333 | G18: =SUM('Working Data'!W235,'Working Data'!V235,'Working Data'!T235,'Working Data'!Q235) -> 596.3 | H18: =(Table11[[#This Row],[Food & Beverages]]-E17)/E17 -> -0.013115483 | I18: =(Table11[[#This Row],[Health and Personal care]]-F17)/F17 -> 0.0027682052 | J18: =(Table11[[#This Row],[Essential]]-G17)/G17 -> 0.037765402 | K18: After Covid
B19: Rural+Urban | C19: 2020 | D19: June | E19: 1966.8 | F19: 306 | G19: =SUM('Working Data'!W236,'Working Data'!V236,'Working Data'!T236,'Working Data'!Q236) -> 612.8 | H19: =(Table11[[#This Row],[Food & Beverages]]-E18)/E18 -> 0.022360453 | I19: =(Table11[[#This Row],[Health and Personal care]]-F18)/F18 -> 0.034366197 | J19: =(Table11[[#This Row],[Essential]]-G18)/G18 -> 0.027670636 | K19: After Covid | M19: 1. Food Inflation (Blue Line):
B20: Rural+Urban | C20: 2020 | D20: July | E20: 1966.8 | F20: 306 | G20: =SUM('Working Data'!W237,'Working Data'!V237,'Working Data'!T237,'Working Data'!Q237) -> 574.5 | H20: =(Table11[[#This Row],[Food & Beverages]]-E19)/E19 -> 0 | I20: =(Table11[[#This Row],[Health and Personal care]]-F19)/F19 -> 0 | J20: =(Table11[[#This Row],[Essential]]-G19)/G19 -> -0.0625 | K20: After Covid | M20: Generally stable with mild monthly fluctuations.
B21: Rural+Urban | C21: 2020 | D21: August | E21: 1995.2 | F21: 309.3 | G21: =SUM('Working Data'!W238,'Working Data'!V238,'Working Data'!T238,'Working Data'!Q238) -> 596.7 | H21: =(Table11[[#This Row],[Food & Beverages]]-E20)/E20 -> 0.014439699 | I21: =(Table11[[#This Row],[Health and Personal care]]-F20)/F20 -> 0.010784314 | J21: =(Table11[[#This Row],[Essential]]-G20)/G20 -> 0.038642298 | K21: After Covid | M21: Ranges mostly between 0% to 2% (0 to 0.02 on the Y-axis).
B22: Rural+Urban | C22: 2020 | D22: September | E22: 2007 | F22: 314 | G22: =SUM('Working Data'!W239,'Working Data'!V239,'Working Data'!T239,'Working Data'!Q239) -> 613.9 | H22: =(Table11[[#This Row],[Food & Beverages]]-E21)/E21 -> 0.0059141941 | I22: =(Table11[[#This Row],[Health and Personal care]]-F21)/F21 -> 0.015195603 | J22: =(Table11[[#This Row],[Essential]]-G21)/G21 -> 0.028825205 | K22: After Covid | M22: Slight upward trend visible toward late 2019.
B23: Rural+Urban | C23: 2020 | D23: October | E23: 2048.6 | F23: 313.3 | G23: =SUM('Working Data'!W240,'Working Data'!V240,'Working Data'!T240,'Working Data'!Q240) -> 576.8 | H23: =(Table11[[#This Row],[Food & Beverages]]-E22)/E22 -> 0.020727454 | I23: =(Table11[[#This Row],[Health and Personal care]]-F22)/F22 -> -0.0022292994 | J23: =(Table11[[#This Row],[Essential]]-G22)/G22 -> -0.060433295 | K23: After Covid
B24: Rural+Urban | C24: 2020 | D24: November | E24: 2095.6 | F24: 314.1 | G24: =SUM('Working Data'!W241,'Working Data'!V241,'Working Data'!T241,'Working Data'!Q241) -> 598.2 | H24: =(Table11[[#This Row],[Food & Beverages]]-E23)/E23 -> 0.022942497 | I24: =(Table11[[#This Row],[Health and Personal care]]-F23)/F23 -> 0.0025534631 | J24: =(Table11[[#This Row],[Essential]]-G23)/G23 -> 0.037101248 | K24: After Covid | M24: 2. Health Inflation (Purple Line):
B25: Rural+Urban | C25: 2020 | D25: December | E25: 2109.1 | F25: 315.4 | G25: =SUM('Working Data'!W242,'Working Data'!V242,'Working Data'!T242,'Working Data'!Q242) -> 615.6 | H25: =(Table11[[#This Row],[Food & Beverages]]-E24)/E24 -> 0.0064420691 | I25: =(Table11[[#This Row],[Health and Personal care]]-F24)/F24 -> 0.0041388093 | J25: =(Table11[[#This Row],[Essential]]-G24)/G24 -> 0.029087262 | K25: After Covid | M25: Remains steady with very little monthly volatility.
B26: Rural+Urban | C26: 2021 | D26: January | E26: 2076.5 | F26: 316.1 | G26: =SUM('Working Data'!W243,'Working Data'!V243,'Working Data'!T243,'Working Data'!Q243) -> 580.8 | H26: =(Table11[[#This Row],[Food & Beverages]]-E25)/E25 -> -0.01545683 | I26: =(Table11[[#This Row],[Health and Personal care]]-F25)/F25 -> 0.0022194039 | J26: =(Table11[[#This Row],[Essential]]-G25)/G25 -> -0.056530214 | K26: After Covid | M26: Mostly hovers between 0% and 1%.
B27: Rural+Urban | C27: 2021 | D27: February | E27: 2039.3 | F27: 317.1 | G27: =SUM('Working Data'!W244,'Working Data'!V244,'Working Data'!T244,'Working Data'!Q244) -> 600.9 | H27: =(Table11[[#This Row],[Food & Beverages]]-E26)/E26 -> -0.01791476 | I27: =(Table11[[#This Row],[Health and Personal care]]-F26)/F26 -> 0.0031635558 | J27: =(Table11[[#This Row],[Essential]]-G26)/G26 -> 0.034607438 | K27: After Covid | M27: Reflects a relatively controlled or regulated health sector prior to the pandemic.
B28: Rural+Urban | C28: 2021 | D28: March | E28: 2039.4 | F28: 315.5 | G28: =SUM('Working Data'!W245,'Working Data'!V245,'Working Data'!T245,'Working Data'!Q245) -> 618 | H28: =(Table11[[#This Row],[Food & Beverages]]-E27)/E27 -> 4.9036434e-05 | I28: =(Table11[[#This Row],[Health and Personal care]]-F27)/F27 -> -0.0050457269 | J28: =(Table11[[#This Row],[Essential]]-G27)/G27 -> 0.028457314 | K28: After Covid
M29: 3. Essential Inflation (Green Line):
M30: Shows a clear seasonal or cyclical pattern, with sharp increases followed by equally sharp declines.
M31: Frequently dips into negative inflation (deflation) territory, sometimes as low as -6%.
M32: This cyclical pattern suggests possible seasonality in essential goods pricing (possibly energy, utilities, etc.).
M34: Insights After March 2020 (Apr 2020 – Mar 2021):
M36: 1. Food Inflation:
M37: Becomes more volatile post-March 2020.
M38: Peaks sharply around April and May 2020, likely due to supply chain disruptions and panic buying during lockdowns.
M39: Although it stabilizes later, the volatility remains slightly higher than pre-pandemic levels.
M41: 2. Health Inflation:
M42: Slightly increases and shows greater variability, especially around June 2020, possibly reflecting higher demand for healthcare services and medical goods.
M43: Suggests pressure on the health sector during the peak pandemic phase.
... M57: Overall, economic volatility increased post-pandemic onset, with inflationary pressures in critical sectors.

Sheet Problem statement 5
B1: Sector | C1: Year | D1: Month | E1: Crude Oil Price | F1: Inflation | G1: Cereals and products | H1: Meat and fish | I1: Egg | J1: Milk and products | K1: Oils and fats | L1: Fruits | M1: Vegetables | N1: Pulses and products | O1: Sugar and Confectionery | P1: Spices | Q1: Non-alcoholic beverages | R1: Prepared meals, snacks, sweets etc. | S1: Food and beverages | T1: Pan, tobacco and intoxicants | U1: Clothing | V1: Footwear | W1: Clothing and footwear | X1: Housing | Y1: Fuel and light | Z1: Household goods and services | AA1: Health | AB1: Transport and communication | AC1: Recreation and amusement | AD1: Education | AE1: Personal care and effects | AF1: Miscellaneous | AG1: General index
B2: Rural+Urban | C2: 2021 | D2: January | E2: 3918.56 | F2: 0.0917 | G2: 144.9 | H2: 190.1 | I2: 175.3 | J2: 154.1 | K2: 150.9 | L2: 149.6 | M2: 194.2 | N2: 160.4 | O2: 114.6 | P2: 164 | Q2: 151.8 | R2: 165.6 | S2: 161 | T2: 186.5 | U2: 155.5 | V2: 146.1 | W2: 154.2 | X2: 157.7 | Y2: 147.9 | Z2: 150 | AA2: 159.3 | AB2: 141.9 | AC2: 149.6 | AD2: 159.2 | AE2: 156.8 | AF2: 151.9 | AG2: 157.3
B3: Rural+Urban | C3: 2021 | D3: February | E3: 4399.41 | F3: 0.1227 | G3: 144.3 | H3: 186.5 | I3: 168.7 | J3: 154.7 | K3: 158.7 | L3: 150.7 | M3: 160 | N3: 158.8 | O3: 112.8 | P3: 164.2 | Q3: 155.5 | R3: 167.5 | S3: 156.9 | T3: 188.3 | U3: 157.2 | V3: 147.4 | W3: 155.8 | X3: 159.8 | Y3: 152.4 | Z3: 150.9 | AA3: 161.3 | AB3: 145.1 | AC3: 151.5 | AD3: 159.5 | AE3: 155.8 | AF3: 153.4 | AG3: 156.6
B4: Rural+Urban | C4: 2021 | D4: March | E4: 4646.36 | F4: 0.0561 | G4: 144.1 | H4: 192.2 | I4: 163.8 | J4: 154.9 | K4: 163.9 | L4: 153.7 | M4: 149.5 | N4: 159.8 | O4: 112.6 | P4: 163.5 | Q4: 156.5 | R4: 168.2 | S4: 156.7 | T4: 188.1 | U4: 157.8 | V4: 147.9 | W4: 156.4 | X4: 159.9 | Y4: 155.5 | Z4: 151.2 | AA4: 161.7 | AB4: 146.2 | AC4: 152.6 | AD4: 160.2 | AE4: 153.8 | AF4: 153.8 | AG4: 156.8
B5: Rural+Urban | C5: 2021 | D5: April | E5: 4684.64 | F5: 0.0082 | G5: 144.3 | H5: 198 | I5: 164.6 | J5: 155.4 | K5: 170.1 | L5: 164.4 | M5: 144.1 | N5: 161.7 | O5: 113.1 | P5: 163.9 | Q5: 157.6 | R5: 168.9 | S5: 158 | T5: 188.8 | U5: 158.8 | V5: 148.5 | W5: 157.3 | X5: 161.4 | Y5: 155.6 | Z5: 151.8 | AA5: 162.3 | AB5: 146.6 | AC5: 153.2 | AD5: 160.3 | AE5: 155.4 | AF5: 154.4 | AG5: 157.8
B6: Rural+Urban | C6: 2021 | D6: May | E6: 4870.98 | F6: 0.0398 | G6: 146.3 | H6: 200.5 | I6: 170.3 | J6: 156.1 | K6: 178.7 | L6: 167.1 | M6: 147.9 | N6: 165.4 | O6: 114.8 | P6: 168.2 | Q6: 159.3 | R6: 170.4 | S6: 160.7 | T6: 191.9 | U6: 161.8 | V6: 152.1 | W6: 160.4 | X6: 161.6 | Y6: 159.4 | Z6: 154.7 | AA6: 165.8 | AB6: 148.9 | AC6: 155.8 | AD6: 161.2 | AE6: 158.6 | AF6: 156.8 | AG6: 160.4
B7: Rural+Urban | C7: 2021 | D7: June | E7: 5281.48 | F7: 0.0843 | G7: 146.7 | H7: 202 | I7: 180.7 | J7: 156.2 | K7: 183.7 | L7: 164.6 | M7: 155.4 | N7: 166 | O7: 115.1 | P7: 168.5 | Q7: 160 | R7: 172.4 | S7: 162.6 | T7: 190.8 | U7: 162.2 | V7: 151.8 | W7: 160.7 | X7: 160.5 | Y7: 159.8 | Z7: 154.8 | AA7: 166.3 | AB7: 150.7 | AC7: 154.9 | AD7: 161.7 | AE7: 158.8 | AF7: 157.6 | AG7: 161.3
B8: Rural+Urban | C8: 2021 | D8: July | E8: 5460.9 | F8: 0.034 | G8: 146.4 | H8: 206.8 | I8: 182.2 | J8: 157.5 | K8: 182.1 | L8: 163.9 | M8: 164.2 | N8: 164 | O8: 114.5 | P8: 168.3 | Q8: 160.9 | R8: 172.2 | S8: 164 | T8: 191.2 | U8: 162.8 | V8: 153.1 | W8: 161.4 | X8: 161.5 | Y8: 160.7 | Z8: 155.8 | AA8: 167 | AB8: 153.1 | AC8: 155.3 | AD8: 163.2 | AE8: 160.1 | AF8: 159 | AG8: 162.5
